<?xml version="1.0" encoding="UTF-8"?>
<testng-results skipped="0" failed="1" total="1" passed="0">
  <reporter-output>
  </reporter-output>
  <suite name="Default suite" duration-ms="41737" started-at="2014-11-27T10:40:41Z" finished-at="2014-11-27T10:41:23Z">
    <groups>
    </groups>
    <test name="Default test" duration-ms="41737" started-at="2014-11-27T10:40:41Z" finished-at="2014-11-27T10:41:23Z">
      <class name="add_new_customer_and_account.GuruTestPage">
        <test-method status="PASS" signature="setUp()[pri:0, instance:add_new_customer_and_account.GuruTestPage@2b80d80f]" name="setUp" is-config="true" duration-ms="34774" started-at="2014-11-27T12:40:41Z" finished-at="2014-11-27T12:41:16Z">
          <reporter-output>
          </reporter-output>
        </test-method> <!-- setUp -->
        <test-method status="FAIL" signature="verify_added_user()[pri:0, instance:add_new_customer_and_account.GuruTestPage@2b80d80f]" name="verify_added_user" duration-ms="6704" started-at="2014-11-27T12:41:16Z" finished-at="2014-11-27T12:41:23Z">
          <exception class="java.lang.AssertionError">
            <message>
              <![CDATA[expected [New user added!] but found [please fill all fields]]]>
            </message>
            <full-stacktrace>
              <![CDATA[java.lang.AssertionError: expected [New user added!] but found [please fill all fields]
	at org.testng.Assert.fail(Assert.java:94)
	at org.testng.Assert.failNotEquals(Assert.java:494)
	at org.testng.Assert.assertEquals(Assert.java:123)
	at org.testng.Assert.assertEquals(Assert.java:176)
	at org.testng.Assert.assertEquals(Assert.java:186)
	at add_new_customer_and_account.GuruResultPage.verify_adding(GuruResultPage.java:17)
	at add_new_customer_and_account.GuruTestPage.verify_added_user(GuruTestPage.java:33)
	at sun.reflect.NativeMethodAccessorImpl.invoke0(Native Method)
	at sun.reflect.NativeMethodAccessorImpl.invoke(Unknown Source)
	at sun.reflect.DelegatingMethodAccessorImpl.invoke(Unknown Source)
	at java.lang.reflect.Method.invoke(Unknown Source)
	at org.testng.internal.MethodInvocationHelper.invokeMethod(MethodInvocationHelper.java:84)
	at org.testng.internal.Invoker.invokeMethod(Invoker.java:714)
	at org.testng.internal.Invoker.invokeTestMethod(Invoker.java:901)
	at org.testng.internal.Invoker.invokeTestMethods(Invoker.java:1231)
	at org.testng.internal.TestMethodWorker.invokeTestMethods(TestMethodWorker.java:127)
	at org.testng.internal.TestMethodWorker.run(TestMethodWorker.java:111)
	at org.testng.TestRunner.privateRun(TestRunner.java:767)
	at org.testng.TestRunner.run(TestRunner.java:617)
	at org.testng.SuiteRunner.runTest(SuiteRunner.java:334)
	at org.testng.SuiteRunner.runSequentially(SuiteRunner.java:329)
	at org.testng.SuiteRunner.privateRun(SuiteRunner.java:291)
	at org.testng.SuiteRunner.run(SuiteRunner.java:240)
	at org.testng.SuiteRunnerWorker.runSuite(SuiteRunnerWorker.java:52)
	at org.testng.SuiteRunnerWorker.run(SuiteRunnerWorker.java:86)
	at org.testng.TestNG.runSuitesSequentially(TestNG.java:1224)
	at org.testng.TestNG.runSuitesLocally(TestNG.java:1149)
	at org.testng.TestNG.run(TestNG.java:1057)
	at org.testng.remote.RemoteTestNG.run(RemoteTestNG.java:111)
	at org.testng.remote.RemoteTestNG.initAndRun(RemoteTestNG.java:204)
	at org.testng.remote.RemoteTestNG.main(RemoteTestNG.java:175)
]]>
            </full-stacktrace>
          </exception> <!-- java.lang.AssertionError -->
          <reporter-output>
          </reporter-output>
        </test-method> <!-- verify_added_user -->
        <test-method status="PASS" signature="tearDown()[pri:0, instance:add_new_customer_and_account.GuruTestPage@2b80d80f]" name="tearDown" is-config="true" duration-ms="236" started-at="2014-11-27T12:41:23Z" finished-at="2014-11-27T12:41:23Z">
          <reporter-output>
          </reporter-output>
        </test-method> <!-- tearDown -->
      </class> <!-- add_new_customer_and_account.GuruTestPage -->
    </test> <!-- Default test -->
  </suite> <!-- Default suite -->
</testng-results>
